Workbook

Sheet README
A1: PREVOLT - Unit Economics Model (prepared 1 Oct 2026)
A2: PURPOSE: test whether a 250 ml canned PREVOLT drink can make money at 2,000 / 5,000 / 10,000 units, for an artificial-powder formulation and three natural-fruit concepts.
A3: THIS IS NOT A QUOTATION. No manufacturer has quoted any natural-fruit formulation. Every natural-fruit cost is HYPOTHETICAL and exists only for sensitivity analysis.
A4: The historical Rs 22/unit (at ~10,000 units, artificial powder, 2025, founder-reported) is shown ONLY on sheet 'Historical_Reference' and is NOT used for natural-fruit scenarios.
A6: INPUT TYPES (cell colour):
A7: HISTORICAL - founder-reported 2025 figure; no document seen; not a current offer.
A8: VERIFIED - read in a primary/regulatory source (see SOURCE_REGISTER.csv id).
A9: RESEARCHED - public benchmark (listing/blog/press); low-medium confidence; not a quote.
A10: ASSUMED - analyst assumption for a first-batch pilot; replace with local data.
A11: HYPOTHETICAL- placeholder range for an unquoted cost (e.g. real blueberry). Must be replaced by a manufacturer quotation.
A12: UNKNOWN - no basis found; placeholder only.
A14: HOW TO USE: edit the BASE column (F) on 'Inputs' and 'Formulation_Inputs'. All other sheets recalculate. LOW/HIGH columns are used by 'Sensitivity'.
... A18: Sheets: Inputs | Formulation_Inputs | Scenarios (12 cases) | Three_Flavour_vs_Staged | Best_Case_Check | Sensitivity | Breakeven_MRP | QComm_D2C | Historical_Reference | Quotes_Required

Sheet Inputs
A1: GLOBAL INPUTS (Rs per can ex-GST unless stated)
A3: Key | B3: Description | C3: Unit | D3: Type | E3: Low | F3: Base | G3: High | H3: Source / rationale
A4: can | B4: Empty 250 ml aluminium can incl. end | C4: Rs/can | D4: RESEARCHED | E4: 10 | F4: 11.5 | G4: 15 | H4: S43 listing ~Rs 11.5; S41 blog Rs 12-15. Printed-can MOQs from large can makers are typically far above pilot volumes: get a quote.
A5: decor | B5: Can decoration: shrink sleeve / label / print premium | C5: Rs/can | D5: ASSUMED | E5: 1 | F5: 2 | G5: 4 | H5: No quote. S41 lists packaging & labelling Rs 2-4 (incl. secondary).
A6: fill | B6: Filling, carbonation, seaming, pasteurisation tolling | C6: Rs/can | D6: RESEARCHED | E6: 3 | F6: 4 | G6: 6 | H6: S41 blog Rs 3-5. Real-fruit pulp may need hot-fill/tunnel pasteurisation: see processing adder.
A7: sec | B7: Secondary packaging (trays, shrink, cartons) | C7: Rs/can | D7: ASSUMED | E7: 1 | F7: 1.5 | G7: 3 | H7: Assumption.
A8: frt | B8: Freight factory -> pilot-city warehouse | C8: Rs/can | D8: ASSUMED | E8: 1 | F8: 2 | G8: 4 | H8: Assumption; depends on distance (Bengaluru plant vs pilot city).
A9: wh | B9: Warehousing & handling (first batch) | C9: Rs/can | D9: ASSUMED | E9: 0.5 | F9: 1 | G9: 2 | H9: Assumption.
A10: setup | B10: Line setup / changeover per flavour batch | C10: Rs/batch | D10: HYPOTHETICAL | E10: 0 | F10: 20000 | G10: 50000 | H10: Unknown. DH Brands claims a no-MOQ semi-auto line (S44); other blogs cite 4-8 h changeover cleaning (S42).
A11: qa | B11: Batch release testing at an accredited lab (micro, caffeine, label claims) per flavour batch | C11: Rs/batch | D11: HYPOTHETICAL | E11: 10000 | F11: 25000 | G11: 50000 | H11: No quote; ask NABL-accredited labs.
A12: waste | B12: Damage / QC rejects | C12: % of units | D12: ASSUMED | E12: 0.01 | F12: 0.03 | G12: 0.06 | H12: Assumption.
A13: samp | B13: Free sampling (tastings, gyms, campuses) | C13: % of units | D13: ASSUMED | E13: 0.05 | F13: 0.1 | G13: 0.2 | H13: Assumption; trial-driven category.
A14: st | B14: Sell-through of saleable stock before expiry/obsolescence | C14: % of saleable | D14: ASSUMED | E14: 0.4 | F14: 0.75 | G14: 0.95 | H14: Assumption: an unknown brand with a first batch. Validate in the pilot.
A15: gst | B15: GST on caffeinated beverages (included in MRP) | C15: % | D15: VERIFIED | E15: 0.4 | F15: 0.4 | G15: 0.4 | H15: S13 Notification 01/2026-CT(Rate): 40%.
... A24: sellmonths | B24: Months to sell one batch | C24: months | D24: ASSUMED | E24: 2 | F24: 3 | G24: 6 | H24: Assumption.

Sheet Formulation_Inputs
A1: FORMULATION-SPECIFIC INPUTS (Rs per can ex-GST). Natural-fruit values are HYPOTHETICAL: no manufacturer has quoted them.
A3: Key | B3: Description | C3: Unit | D3: Powder (artificial flavour) | E3: Blueberry (real fruit/juice) | F3: Lemon (juice/natural flavour) | G3: Coconut (coconut-water base) | H3: Type | I3: Rationale | J3: Rationale
A4: ing | B4: Base ingredient system: sweetener, acids, caffeine, taurine/vitamins, preservative, flavour | C4: Rs/can | D4: 8 | E4: 8 | F4: 8 | G4: 6 | H4: RESEARCHED | I4: S41 blog Rs 8-12 (generic). Coconut base assumes coconut water replaces most water.
A5: fruit | B5: Fruit adder: real fruit/juice/puree/concentrate or natural flavour system | C5: Rs/can | D5: 0 | E5: 12 | F5: 2 | G5: 15 | H5: HYPOTHETICAL | I5: NO PRICE FOUND. Blueberry largely imported; coconut water is most of the fill volume. Range used in Sensitivity: Bb 5-25, Le 1-5, Co 8-25.
A6: proc | B6: Processing adder: stabiliser, homogenisation, hot-fill/tunnel pasteurisation, O2 control, low-acid controls | C6: Rs/can | D6: 0 | E6: 2 | F6: 0.5 | G6: 4 | H6: HYPOTHETICAL | I6: Coconut water perishable/enzymatic (S57); anthocyanins heat-labile (S54).
A7: npd | B7: New product development fee per flavour | C7: Rs | D7: 25000 | E7: 100000 | F7: 75000 | G7: 150000 | H7: HYPOTHETICAL | I7: Placeholder. Request quotes from 3 manufacturers.
A8: shelf | B8: Shelf-life & stability study per flavour | C8: Rs | D8: 30000 | E8: 60000 | F8: 50000 | G8: 75000 | H8: HYPOTHETICAL | I8: Placeholder. Coconut low-acid validation may cost more.

Sheet Scenarios
A1: SCENARIOS: one flavour per column. Volumes are per flavour. All values Rs ex-GST unless stated.
A3: Line item | B3: Formula / note | C3: Powder 2,000 | D3: Powder 5,000 | E3: Powder 10,000 | F3: Blueberry 2,000 | G3: Blueberry 5,000 | H3: Blueberry 10,000 | I3: Lemon 2,000 | J3: Lemon 5,000 | K3: Lemon 10,000 | L3: Coconut 2,000 | M3: Coconut 5,000 | N3: Coconut 10,000
A5: Formulation index (0 Powder,1 Blueberry,2 Lemon,3 Coconut) | C5: 0 | D5: 0 | E5: 0 | F5: 1 | G5: 1 | H5: 1 | I5: 2 | J5: 2 | K5: 2 | L5: 3 | M5: 3 | N5: 3
A6: Units produced (this flavour) | C6: 2000 | D6: 5000 | E6: 10000 | F6: 2000 | G6: 5000 | H6: 10000 | I6: 2000 | J6: 5000 | K6: 10000 | L6: 2000 | M6: 5000 | N6: 10000
A7: Variable cost per can produced | C7: =Inputs!$F$4+Inputs!$F$5+Formulation_Inputs!$D$4+Formulation_Inputs!$D$5+Formulation_Inputs!$D$6+Inputs!$F$6+Inputs!$F$7+Inputs!$F$8+Inputs!$F$9 | D7: =Inputs!$F$4+Inputs!$F$5+Formulation_Inputs!$D$4+Formulation_Inputs!$D$5+Formulation_Inputs!$D$6+Inputs!$F$6+Inputs!$F$7+Inputs!$F$8+Inputs!$F$9 | E7: =Inputs!$F$4+Inputs!$F$5+Formulation_Inputs!$D$4+Formulation_Inputs!$D$5+Formulation_Inputs!$D$6+Inputs!$F$6+Inputs!$F$7+Inputs!$F$8+Inputs!$F$9 | F7: =Inputs!$F$4+Inputs!$F$5+Formulation_Inputs!$E$4+Formulation_Inputs!$E$5+Formulation_Inputs!$E$6+Inputs!$F$6+Inputs!$F$7+Inputs!$F$8+Inputs!$F$9 | G7: =Inputs!$F$4+Inputs!$F$5+Formulation_Inputs!$E$4+Formulation_Inputs!$E$5+Formulation_Inputs!$E$6+Inputs!$F$6+Inputs!$F$7+Inputs!$F$8+Inputs!$F$9 | H7: =Inputs!$F$4+Inputs!$F$5+Formulation_Inputs!$E$4+Formulation_Inputs!$E$5+Formulation_Inputs!$E$6+Inputs!$F$6+Inputs!$F$7+Inputs!$F$8+Inputs!$F$9 | I7: =Inputs!$F$4+Inputs!$F$5+Formulation_Inputs!$F$4+Formulation_Inputs!$F$5+Formulation_Inputs!$F$6+Inputs!$F$6+Inputs!$F$7+Inputs!$F$8+Inputs!$F$9 | J7: =Inputs!$F$4+Inputs!$F$5+Formulation_Inputs!$F$4+Formulation_Inputs!$F$5+Formulation_Inputs!$F$6+Inputs!$F$6+Inputs!$F$7+Inputs!$F$8+Inputs!$F$9 | K7: =Inputs!$F$4+Inputs!$F$5+Formulation_Inputs!$F$4+Formulation_Inputs!$F$5+Formulation_Inputs!$F$6+Inputs!$F$6+Inputs!$F$7+Inputs!$F$8+Inputs!$F$9 | L7: =Inputs!$F$4+Inputs!$F$5+Formulation_Inputs!$G$4+Formulation_Inputs!$G$5+Formulation_Inputs!$G$6+Inputs!$F$6+Inputs!$F$7+Inputs!$F$8+Inputs!$F$9 | M7: =Inputs!$F$4+Inputs!$F$5+Formulation_Inputs!$G$4+Formulation_Inputs!$G$5+Formulation_Inputs!$G$6+Inputs!$F$6+Inputs!$F$7+Inputs!$F$8+Inputs!$F$9 | N7: =Inputs!$F$4+Inputs!$F$5+Formulation_Inputs!$G$4+Formulation_Inputs!$G$5+Formulation_Inputs!$G$6+Inputs!$F$6+Inputs!$F$7+Inputs!$F$8+Inputs!$F$9
A8: Batch fixed costs (setup + release testing) | C8: =Inputs!$F$10+Inputs!$F$11 | D8: =Inputs!$F$10+Inputs!$F$11 | E8: =Inputs!$F$10+Inputs!$F$11 | F8: =Inputs!$F$10+Inputs!$F$11 | G8: =Inputs!$F$10+Inputs!$F$11 | H8: =Inputs!$F$10+Inputs!$F$11 | I8: =Inputs!$F$10+Inputs!$F$11 | J8: =Inputs!$F$10+Inputs!$F$11 | ... N8: =Inputs!$F$10+Inputs!$F$11
A9: Batch fixed cost per can | C9: =C8/C6 | D9: =D8/D6 | E9: =E8/E6 | F9: =F8/F6 | G9: =G8/G6 | H9: =H8/H6 | I9: =I8/I6 | J9: =J8/J6 | ... N9: =N8/N6
A10: Production cash cost of batch | C10: =C6*C7+C8 | D10: =D6*D7+D8 | E10: =E6*E7+E8 | F10: =F6*F7+F8 | G10: =G6*G7+G8 | H10: =H6*H7+H8 | I10: =I6*I7+I8 | J10: =J6*J7+J8 | ... N10: =N6*N7+N8
A11: Production cost per can produced | C11: =C10/C6 | D11: =D10/D6 | E11: =E10/E6 | F11: =F10/F6 | G11: =G10/G6 | H11: =H10/H6 | I11: =I10/I6 | J11: =J10/J6 | ... N11: =N10/N6
A12: One-time costs attributable to this flavour (NPD + shelf-life + 1/3 of shared reg/design/licence) | C12: =Formulation_Inputs!$D$7+Formulation_Inputs!$D$8+(Inputs!$F$20+Inputs!$F$21+Inputs!$F$22)/3 | D12: =Formulation_Inputs!$D$7+Formulation_Inputs!$D$8+(Inputs!$F$20+Inputs!$F$21+Inputs!$F$22)/3 | E12: =Formulation_Inputs!$D$7+Formulation_Inputs!$D$8+(Inputs!$F$20+Inputs!$F$21+Inputs!$F$22)/3 | F12: =Formulation_Inputs!$E$7+Formulation_Inputs!$E$8+(Inputs!$F$20+Inputs!$F$21+Inputs!$F$22)/3 | G12: =Formulation_Inputs!$E$7+Formulation_Inputs!$E$8+(Inputs!$F$20+Inputs!$F$21+Inputs!$F$22)/3 | H12: =Formulation_Inputs!$E$7+Formulation_Inputs!$E$8+(Inputs!$F$20+Inputs!$F$21+Inputs!$F$22)/3 | I12: =Formulation_Inputs!$F$7+Formulation_Inputs!$F$8+(Inputs!$F$20+Inputs!$F$21+Inputs!$F$22)/3 | J12: =Formulation_Inputs!$F$7+Formulation_Inputs!$F$8+(Inputs!$F$20+Inputs!$F$21+Inputs!$F$22)/3 | K12: =Formulation_Inputs!$F$7+Formulation_Inputs!$F$8+(Inputs!$F$20+Inputs!$F$21+Inputs!$F$22)/3 | L12: =Formulation_Inputs!$G$7+Formulation_Inputs!$G$8+(Inputs!$F$20+Inputs!$F$21+Inputs!$F$22)/3 | M12: =Formulation_Inputs!$G$7+Formulation_Inputs!$G$8+(Inputs!$F$20+Inputs!$F$21+Inputs!$F$22)/3 | N12: =Formulation_Inputs!$G$7+Formulation_Inputs!$G$8+(Inputs!$F$20+Inputs!$F$21+Inputs!$F$22)/3
A13: Units lost to damage/QC | C13: =C6*Inputs!$F$12 | D13: =D6*Inputs!$F$12 | E13: =E6*Inputs!$F$12 | F13: =F6*Inputs!$F$12 | G13: =G6*Inputs!$F$12 | H13: =H6*Inputs!$F$12 | I13: =I6*Inputs!$F$12 | J13: =J6*Inputs!$F$12 | ... N13: =N6*Inputs!$F$12
A14: Units given as free samples | C14: =C6*Inputs!$F$13 | D14: =D6*Inputs!$F$13 | E14: =E6*Inputs!$F$13 | F14: =F6*Inputs!$F$13 | G14: =G6*Inputs!$F$13 | H14: =H6*Inputs!$F$13 | I14: =I6*Inputs!$F$13 | J14: =J6*Inputs!$F$13 | ... N14: =N6*Inputs!$F$13
A15: Saleable units | C15: =C6-C13-C14 | D15: =D6-D13-D14 | E15: =E6-E13-E14 | F15: =F6-F13-F14 | G15: =G6-G13-G14 | H15: =H6-H13-H14 | I15: =I6-I13-I14 | J15: =J6-J13-J14 | ... N15: =N6-N13-N14
A16: Units sold (saleable x sell-through) | C16: =C15*Inputs!$F$14 | D16: =D15*Inputs!$F$14 | E16: =E15*Inputs!$F$14 | F16: =F15*Inputs!$F$14 | G16: =G15*Inputs!$F$14 | H16: =H15*Inputs!$F$14 | I16: =I15*Inputs!$F$14 | J16: =J15*Inputs!$F$14 | ... N16: =N15*Inputs!$F$14
A17: Unsold / expired units | C17: =C15-C16 | D17: =D15-D16 | E17: =E15-E16 | F17: =F15-F16 | G17: =G15-G16 | H17: =H15-H16 | I17: =I15-I16 | J17: =J15-J16 | ... N17: =N15-N16
A18: MRP (incl. 40% GST) | C18: =Inputs!$F$16 | D18: =Inputs!$F$16 | E18: =Inputs!$F$16 | F18: =Inputs!$F$16 | G18: =Inputs!$F$16 | H18: =Inputs!$F$16 | I18: =Inputs!$F$16 | J18: =Inputs!$F$16 | ... N18: =Inputs!$F$16
A19: MRP ex-GST | C19: =C18/(1+Inputs!$F$15) | D19: =D18/(1+Inputs!$F$15) | E19: =E18/(1+Inputs!$F$15) | F19: =F18/(1+Inputs!$F$15) | G19: =G18/(1+Inputs!$F$15) | H19: =H18/(1+Inputs!$F$15) | I19: =I18/(1+Inputs!$F$15) | J19: =J18/(1+Inputs!$F$15) | ... N19: =N18/(1+Inputs!$F$15)
A20: GST per can paid to government | C20: =C18-C19 | D20: =D18-D19 | E20: =E18-E19 | F20: =F18-F19 | G20: =G18-G19 | H20: =H18-H19 | I20: =I18-I19 | J20: =J18-J19 | ... N20: =N18-N19
A21: Retailer margin per can | C21: =C19*Inputs!$F$17 | D21: =D19*Inputs!$F$17 | E21: =E19*Inputs!$F$17 | F21: =F19*Inputs!$F$17 | G21: =G19*Inputs!$F$17 | H21: =H19*Inputs!$F$17 | I21: =I19*Inputs!$F$17 | J21: =J19*Inputs!$F$17 | ... N21: =N19*Inputs!$F$17
A22: Distributor margin per can | C22: =(C19-C21)*Inputs!$F$18 | D22: =(D19-D21)*Inputs!$F$18 | E22: =(E19-E21)*Inputs!$F$18 | F22: =(F19-F21)*Inputs!$F$18 | G22: =(G19-G21)*Inputs!$F$18 | H22: =(H19-H21)*Inputs!$F$18 | I22: =(I19-I21)*Inputs!$F$18 | J22: =(J19-J21)*Inputs!$F$18 | ... N22: =(N19-N21)*Inputs!$F$18
A23: NET REALISATION to brand per can sold | C23: =C19-C21-C22 | D23: =D19-D21-D22 | E23: =E19-E21-E22 | F23: =F19-F21-F22 | G23: =G19-G21-G22 | H23: =H19-H21-H22 | I23: =I19-I21-I22 | J23: =J19-J21-J22 | ... N23: =N19-N21-N22
A24: Revenue (net realisation x units sold) | C24: =C23*C16 | D24: =D23*D16 | E24: =E23*E16 | F24: =F23*F16 | G24: =G23*G16 | H24: =H23*H16 | I24: =I23*I16 | J24: =J23*J16 | ... N24: =N23*N16
A25: Batch gross contribution (revenue - production cash cost) | C25: =C24-C10 | D25: =D24-D10 | E25: =E24-E10 | F25: =F24-F10 | G25: =G24-G10 | H25: =H24-H10 | I25: =I24-I10 | J25: =J24-J10 | ... N25: =N24-N10
A26: Production cost per can SOLD (absorbs waste, samples, unsold) | C26: =C10/C16 | D26: =D10/D16 | E26: =E10/E16 | F26: =F10/F16 | G26: =G10/G16 | H26: =H10/H16 | I26: =I10/I16 | J26: =J10/J16 | ... N26: =N10/N16
A27: Contribution per can sold | C27: =C23-C26 | D27: =D23-D26 | E27: =E23-E26 | F27: =F23-F26 | G27: =G23-G26 | H27: =H23-H26 | I27: =I23-I26 | J27: =J23-J26 | ... N27: =N23-N26
A28: Contribution margin % of net realisation | C28: =C27/C23 | D28: =D27/D23 | E28: =E27/E23 | F28: =F27/F23 | G28: =G27/G23 | H28: =H27/H23 | I28: =I27/I23 | J28: =J27/J23 | ... N28: =N27/N23
A29: Contribution after one-time costs and launch marketing | C29: =C25-C12-Inputs!$F$19 | D29: =D25-D12-Inputs!$F$19 | E29: =E25-E12-Inputs!$F$19 | F29: =F25-F12-Inputs!$F$19 | G29: =G25-G12-Inputs!$F$19 | H29: =H25-H12-Inputs!$F$19 | I29: =I25-I12-Inputs!$F$19 | J29: =J25-J12-Inputs!$F$19 | ... N29: =N25-N12-Inputs!$F$19
A30: Variable cost per can sold (excl. batch fixed) | C30: =C7*C6/C16 | D30: =D7*D6/D16 | E30: =E7*E6/E16 | F30: =F7*F6/F16 | G30: =G7*G6/G16 | H30: =H7*H6/H16 | I30: =I7*I6/I16 | J30: =J7*J6/J16 | ... N30: =N7*N6/N16
A31: Break-even units SOLD to recover batch fixed + one-time + launch (if contribution > 0) | C31: =IF(C23-C30>0,(C8+C12+Inputs!$F$19)/(C23-C30),"NOT REACHABLE at this MRP") | D31: =IF(D23-D30>0,(D8+D12+Inputs!$F$19)/(D23-D30),"NOT REACHABLE at this MRP") | E31: =IF(E23-E30>0,(E8+E12+Inputs!$F$19)/(E23-E30),"NOT REACHABLE at this MRP") | F31: =IF(F23-F30>0,(F8+F12+Inputs!$F$19)/(F23-F30),"NOT REACHABLE at this MRP") | G31: =IF(G23-G30>0,(G8+G12+Inputs!$F$19)/(G23-G30),"NOT REACHABLE at this MRP") | H31: =IF(H23-H30>0,(H8+H12+Inputs!$F$19)/(H23-H30),"NOT REACHABLE at this MRP") | I31: =IF(I23-I30>0,(I8+I12+Inputs!$F$19)/(I23-I30),"NOT REACHABLE at this MRP") | J31: =IF(J23-J30>0,(J8+J12+Inputs!$F$19)/(J23-J30),"NOT REACHABLE at this MRP") | ... N31: =IF(N23-N30>0,(N8+N12+Inputs!$F$19)/(N23-N30),"NOT REACHABLE at this MRP")
A32: Receivables float (credit days / selling period x revenue) | C32: =C24*Inputs!$F$23/(Inputs!$F$24*30) | D32: =D24*Inputs!$F$23/(Inputs!$F$24*30) | E32: =E24*Inputs!$F$23/(Inputs!$F$24*30) | F32: =F24*Inputs!$F$23/(Inputs!$F$24*30) | G32: =G24*Inputs!$F$23/(Inputs!$F$24*30) | H32: =H24*Inputs!$F$23/(Inputs!$F$24*30) | I32: =I24*Inputs!$F$23/(Inputs!$F$24*30) | J32: =J24*Inputs!$F$23/(Inputs!$F$24*30) | ... N32: =N24*Inputs!$F$23/(Inputs!$F$24*30)
A33: FIRST-BATCH CASH NEED (production + one-time + launch + receivables) | C33: =C10+C12+Inputs!$F$19+C32 | D33: =D10+D12+Inputs!$F$19+D32 | E33: =E10+E12+Inputs!$F$19+E32 | F33: =F10+F12+Inputs!$F$19+F32 | G33: =G10+G12+Inputs!$F$19+G32 | H33: =H10+H12+Inputs!$F$19+H32 | I33: =I10+I12+Inputs!$F$19+I32 | J33: =J10+J12+Inputs!$F$19+J32 | ... N33: =N10+N12+Inputs!$F$19+N32

Sheet Best_Case_Check
A1: WHAT MUST BE TRUE: same model with every cost at LOW and every revenue driver at its favourable value (per can produced, 10,000 units per flavour)
A2: Favourable settings: can, decoration, filling, secondary, freight, warehousing, setup, QA at LOW; waste 1%, samples 5%, sell-through 95%, retailer 10%, distributor 5%; fruit and processing adders at their LOW hypothetical values.
A4: Formulation | B4: Variable cost/can (best) | C4: Batch fixed/can | D4: NR per can at MRP Rs 70 | E4: Contribution/can produced at Rs 70 | F4: NR at Rs 99 | G4: Contribution/can produced at Rs 99 | H4: NR at Rs 125 | I4: Contribution/can produced at Rs 125
A5: Powder (artificial flavour) | B5: =Inputs!$E$4+Inputs!$E$5+Formulation_Inputs!$D$4+0+0+Inputs!$E$6+Inputs!$E$7+Inputs!$E$8+Inputs!$E$9 | C5: =(Inputs!$E$10+Inputs!$E$11)/10000 | D5: =70/(1+Inputs!$F$15)*(1-0.10)*(1-0.05) | E5: =D5*(1-0.01-0.05)*0.95-B5-C5 | F5: =99/(1+Inputs!$F$15)*(1-0.10)*(1-0.05) | G5: =F5*(1-0.01-0.05)*0.95-B5-C5 | H5: =125/(1+Inputs!$F$15)*(1-0.10)*(1-0.05) | I5: =H5*(1-0.01-0.05)*0.95-B5-C5
A6: Blueberry (real fruit/juice) | B6: =Inputs!$E$4+Inputs!$E$5+Formulation_Inputs!$E$4+5+0+Inputs!$E$6+Inputs!$E$7+Inputs!$E$8+Inputs!$E$9 | C6: =(Inputs!$E$10+Inputs!$E$11)/10000 | D6: =70/(1+Inputs!$F$15)*(1-0.10)*(1-0.05) | E6: =D6*(1-0.01-0.05)*0.95-B6-C6 | F6: =99/(1+Inputs!$F$15)*(1-0.10)*(1-0.05) | G6: =F6*(1-0.01-0.05)*0.95-B6-C6 | H6: =125/(1+Inputs!$F$15)*(1-0.10)*(1-0.05) | I6: =H6*(1-0.01-0.05)*0.95-B6-C6
A7: Lemon (juice/natural flavour) | B7: =Inputs!$E$4+Inputs!$E$5+Formulation_Inputs!$F$4+1+0+Inputs!$E$6+Inputs!$E$7+Inputs!$E$8+Inputs!$E$9 | C7: =(Inputs!$E$10+Inputs!$E$11)/10000 | D7: =70/(1+Inputs!$F$15)*(1-0.10)*(1-0.05) | E7: =D7*(1-0.01-0.05)*0.95-B7-C7 | F7: =99/(1+Inputs!$F$15)*(1-0.10)*(1-0.05) | G7: =F7*(1-0.01-0.05)*0.95-B7-C7 | H7: =125/(1+Inputs!$F$15)*(1-0.10)*(1-0.05) | I7: =H7*(1-0.01-0.05)*0.95-B7-C7
A8: Coconut (coconut-water base) | B8: =Inputs!$E$4+Inputs!$E$5+Formulation_Inputs!$G$4+8+2+Inputs!$E$6+Inputs!$E$7+Inputs!$E$8+Inputs!$E$9 | C8: =(Inputs!$E$10+Inputs!$E$11)/10000 | D8: =70/(1+Inputs!$F$15)*(1-0.10)*(1-0.05) | E8: =D8*(1-0.01-0.05)*0.95-B8-C8 | F8: =99/(1+Inputs!$F$15)*(1-0.10)*(1-0.05) | G8: =F8*(1-0.01-0.05)*0.95-B8-C8 | H8: =125/(1+Inputs!$F$15)*(1-0.10)*(1-0.05) | I8: =H8*(1-0.01-0.05)*0.95-B8-C8
A10: Reading: under favourable assumptions most formulations earn a positive contribution per can at Rs 99-125 but not reliably at Rs 70. Whether reality sits nearer Base or Best is exactly what the quotations and the pilot must establish.

Sheet Three_Flavour_vs_Staged
A1: DOES A THREE-FLAVOUR LAUNCH MAKE SENSE? Cash and risk comparison (links to Scenarios)
A3: Option | B3: Units produced | C3: Production cash | D3: One-time costs | E3: Launch | F3: First-batch cash need | G3: Units that must sell to recover all costs | H3: Batch contribution after one-time + launch | I3: Note
A4: A. One flavour (Lemon) x 2,000 | B4: =Scenarios!I6 | C4: =Scenarios!I10 | D4: =Scenarios!I12 | E4: =Inputs!$F$19*1 | F4: =Scenarios!I10+Scenarios!I12+Scenarios!I32+E4 | G4: =IF(AND(ISNUMBER(Scenarios!I31)),Scenarios!I31,"NOT REACHABLE at base MRP") | H4: =Scenarios!I25-D4-E4 | I4: Lowest cash; tests demand; cheapest fruit system (hypothetical).
A5: B. One flavour (Blueberry) x 5,000 | B5: =Scenarios!G6 | C5: =Scenarios!G10 | D5: =Scenarios!G12 | E5: =Inputs!$F$19*1 | F5: =Scenarios!G10+Scenarios!G12+Scenarios!G32+E5 | G5: =IF(AND(ISNUMBER(Scenarios!G31)),Scenarios!G31,"NOT REACHABLE at base MRP") | H5: =Scenarios!G25-D5-E5 | I5: Founder-preferred flavour; hypothetical blueberry cost dominates.
A6: C. Three flavours x 2,000 each (MOQ each) | B6: =Scenarios!F6+Scenarios!I6+Scenarios!L6 | C6: =Scenarios!F10+Scenarios!I10+Scenarios!L10 | D6: =Scenarios!F12+Scenarios!I12+Scenarios!L12 | E6: =Inputs!$F$19*3 | F6: =Scenarios!F10+Scenarios!F12+Scenarios!F32+Scenarios!I10+Scenarios!I12+Scenarios!I32+Scenarios!L10+Scenarios!L12+Scenarios!L32+E6 | G6: =IF(AND(ISNUMBER(Scenarios!F31),ISNUMBER(Scenarios!I31),ISNUMBER(Scenarios!L31)),Scenarios!F31+Scenarios!I31+Scenarios!L31,"NOT REACHABLE at base MRP") | H6: =Scenarios!F25+Scenarios!I25+Scenarios!L25-D6-E6 | I6: MOQ applies per flavour (S42 indicates per-SKU batches). Three R&D and shelf-life programmes.
A7: D. Three flavours x 10,000 each (lower-cost tier) | B7: =Scenarios!H6+Scenarios!K6+Scenarios!N6 | C7: =Scenarios!H10+Scenarios!K10+Scenarios!N10 | D7: =Scenarios!H12+Scenarios!K12+Scenarios!N12 | E7: =Inputs!$F$19*3 | F7: =Scenarios!H10+Scenarios!H12+Scenarios!H32+Scenarios!K10+Scenarios!K12+Scenarios!K32+Scenarios!N10+Scenarios!N12+Scenarios!N32+E7 | G7: =IF(AND(ISNUMBER(Scenarios!H31),ISNUMBER(Scenarios!K31),ISNUMBER(Scenarios!N31)),Scenarios!H31+Scenarios!K31+Scenarios!N31,"NOT REACHABLE at base MRP") | H7: =Scenarios!H25+Scenarios!K25+Scenarios!N25-D7-E7 | I7: Needed to reach the historical low unit-cost volume for EACH flavour: 30,000 cans.
A8: E. Staged: Lemon 5,000 then add Blueberry only after the go/no-go gate | B8: =Scenarios!J6 | C8: =Scenarios!J10 | D8: =Scenarios!J12 | E8: =Inputs!$F$19*1 | F8: =Scenarios!J10+Scenarios!J12+Scenarios!J32+E8 | G8: =IF(AND(ISNUMBER(Scenarios!J31)),Scenarios!J31,"NOT REACHABLE at base MRP") | H8: =Scenarios!J25-D8-E8 | I8: Second flavour funded from evidence, not upfront.
A10: Note: launch marketing is scaled by number of flavours for multi-flavour options (assumption). NOT REACHABLE means at least one flavour loses money on every can sold at the current MRP and margins.

Sheet Sensitivity
A1: SENSITIVITY: contribution per can PRODUCED and batch result, one parameter at a time (others at Base)
A2: Closed form: contribution per produced can = NR x (1-waste-samples) x sell-through - variable cost - batch fixed/V; NR = MRP/(1+GST) x (1-ret) x (1-dist)
A4: Blueberry (real fruit/juice) - 5,000 units
A5: Parameter varied | B5: Value | C5: Contribution per can produced (Rs) | D5: Batch result after one-time + launch (Rs)
A6: MRP Rs | B6: 60 | C6: =((60/(1+Inputs!$F$15)*(1-Inputs!$F$17)*(1-Inputs!$F$18))*(1-Inputs!$F$12-Inputs!$F$13)*Inputs!$F$14-Scenarios!G7-Scenarios!G8/5000) | D6: =(((60/(1+Inputs!$F$15)*(1-Inputs!$F$17)*(1-Inputs!$F$18))*(1-Inputs!$F$12-Inputs!$F$13)*Inputs!$F$14-Scenarios!G7-Scenarios!G8/5000)*5000-Scenarios!G12-Inputs!$F$19)
A7: MRP Rs | B7: 70 | C7: =((70/(1+Inputs!$F$15)*(1-Inputs!$F$17)*(1-Inputs!$F$18))*(1-Inputs!$F$12-Inputs!$F$13)*Inputs!$F$14-Scenarios!G7-Scenarios!G8/5000) | D7: =(((70/(1+Inputs!$F$15)*(1-Inputs!$F$17)*(1-Inputs!$F$18))*(1-Inputs!$F$12-Inputs!$F$13)*Inputs!$F$14-Scenarios!G7-Scenarios!G8/5000)*5000-Scenarios!G12-Inputs!$F$19)
A8: MRP Rs | B8: 80 | C8: =((80/(1+Inputs!$F$15)*(1-Inputs!$F$17)*(1-Inputs!$F$18))*(1-Inputs!$F$12-Inputs!$F$13)*Inputs!$F$14-Scenarios!G7-Scenarios!G8/5000) | D8: =(((80/(1+Inputs!$F$15)*(1-Inputs!$F$17)*(1-Inputs!$F$18))*(1-Inputs!$F$12-Inputs!$F$13)*Inputs!$F$14-Scenarios!G7-Scenarios!G8/5000)*5000-Scenarios!G12-Inputs!$F$19)
A9: MRP Rs | B9: 99 | C9: =((99/(1+Inputs!$F$15)*(1-Inputs!$F$17)*(1-Inputs!$F$18))*(1-Inputs!$F$12-Inputs!$F$13)*Inputs!$F$14-Scenarios!G7-Scenarios!G8/5000) | D9: =(((99/(1+Inputs!$F$15)*(1-Inputs!$F$17)*(1-Inputs!$F$18))*(1-Inputs!$F$12-Inputs!$F$13)*Inputs!$F$14-Scenarios!G7-Scenarios!G8/5000)*5000-Scenarios!G12-Inputs!$F$19)
A10: MRP Rs | B10: 125 | C10: =((125/(1+Inputs!$F$15)*(1-Inputs!$F$17)*(1-Inputs!$F$18))*(1-Inputs!$F$12-Inputs!$F$13)*Inputs!$F$14-Scenarios!G7-Scenarios!G8/5000) | D10: =(((125/(1+Inputs!$F$15)*(1-Inputs!$F$17)*(1-Inputs!$F$18))*(1-Inputs!$F$12-Inputs!$F$13)*Inputs!$F$14-Scenarios!G7-Scenarios!G8/5000)*5000-Scenarios!G12-Inputs!$F$19)
A11: Retailer margin | B11: 0.1 | C11: =((Inputs!$F$16/(1+Inputs!$F$15)*(1-0.1)*(1-Inputs!$F$18))*(1-Inputs!$F$12-Inputs!$F$13)*Inputs!$F$14-Scenarios!G7-Scenarios!G8/5000) | D11: =(((Inputs!$F$16/(1+Inputs!$F$15)*(1-0.1)*(1-Inputs!$F$18))*(1-Inputs!$F$12-Inputs!$F$13)*Inputs!$F$14-Scenarios!G7-Scenarios!G8/5000)*5000-Scenarios!G12-Inputs!$F$19)
A12: Retailer margin | B12: 0.2 | C12: =((Inputs!$F$16/(1+Inputs!$F$15)*(1-0.2)*(1-Inputs!$F$18))*(1-Inputs!$F$12-Inputs!$F$13)*Inputs!$F$14-Scenarios!G7-Scenarios!G8/5000) | D12: =(((Inputs!$F$16/(1+Inputs!$F$15)*(1-0.2)*(1-Inputs!$F$18))*(1-Inputs!$F$12-Inputs!$F$13)*Inputs!$F$14-Scenarios!G7-Scenarios!G8/5000)*5000-Scenarios!G12-Inputs!$F$19)
A13: Retailer margin | B13: 0.3 | C13: =((Inputs!$F$16/(1+Inputs!$F$15)*(1-0.3)*(1-Inputs!$F$18))*(1-Inputs!$F$12-Inputs!$F$13)*Inputs!$F$14-Scenarios!G7-Scenarios!G8/5000) | D13: =(((Inputs!$F$16/(1+Inputs!$F$15)*(1-0.3)*(1-Inputs!$F$18))*(1-Inputs!$F$12-Inputs!$F$13)*Inputs!$F$14-Scenarios!G7-Scenarios!G8/5000)*5000-Scenarios!G12-Inputs!$F$19)
A14: Retailer margin | B14: 0.35 | C14: =((Inputs!$F$16/(1+Inputs!$F$15)*(1-0.35)*(1-Inputs!$F$18))*(1-Inputs!$F$12-Inputs!$F$13)*Inputs!$F$14-Scenarios!G7-Scenarios!G8/5000) | D14: =(((Inputs!$F$16/(1+Inputs!$F$15)*(1-0.35)*(1-Inputs!$F$18))*(1-Inputs!$F$12-Inputs!$F$13)*Inputs!$F$14-Scenarios!G7-Scenarios!G8/5000)*5000-Scenarios!G12-Inputs!$F$19)
A15: Sell-through | B15: 0.4 | C15: =((Inputs!$F$16/(1+Inputs!$F$15)*(1-Inputs!$F$17)*(1-Inputs!$F$18))*(1-Inputs!$F$12-Inputs!$F$13)*0.4-Scenarios!G7-Scenarios!G8/5000) | D15: =(((Inputs!$F$16/(1+Inputs!$F$15)*(1-Inputs!$F$17)*(1-Inputs!$F$18))*(1-Inputs!$F$12-Inputs!$F$13)*0.4-Scenarios!G7-Scenarios!G8/5000)*5000-Scenarios!G12-Inputs!$F$19)
A16: Sell-through | B16: 0.6 | C16: =((Inputs!$F$16/(1+Inputs!$F$15)*(1-Inputs!$F$17)*(1-Inputs!$F$18))*(1-Inputs!$F$12-Inputs!$F$13)*0.6-Scenarios!G7-Scenarios!G8/5000) | D16: =(((Inputs!$F$16/(1+Inputs!$F$15)*(1-Inputs!$F$17)*(1-Inputs!$F$18))*(1-Inputs!$F$12-Inputs!$F$13)*0.6-Scenarios!G7-Scenarios!G8/5000)*5000-Scenarios!G12-Inputs!$F$19)
A17: Sell-through | B17: 0.75 | C17: =((Inputs!$F$16/(1+Inputs!$F$15)*(1-Inputs!$F$17)*(1-Inputs!$F$18))*(1-Inputs!$F$12-Inputs!$F$13)*0.75-Scenarios!G7-Scenarios!G8/5000) | D17: =(((Inputs!$F$16/(1+Inputs!$F$15)*(1-Inputs!$F$17)*(1-Inputs!$F$18))*(1-Inputs!$F$12-Inputs!$F$13)*0.75-Scenarios!G7-Scenarios!G8/5000)*5000-Scenarios!G12-Inputs!$F$19)
A18: Sell-through | B18: 0.95 | C18: =((Inputs!$F$16/(1+Inputs!$F$15)*(1-Inputs!$F$17)*(1-Inputs!$F$18))*(1-Inputs!$F$12-Inputs!$F$13)*0.95-Scenarios!G7-Scenarios!G8/5000) | D18: =(((Inputs!$F$16/(1+Inputs!$F$15)*(1-Inputs!$F$17)*(1-Inputs!$F$18))*(1-Inputs!$F$12-Inputs!$F$13)*0.95-Scenarios!G7-Scenarios!G8/5000)*5000-Scenarios!G12-Inputs!$F$19)
A19: Sampling % | B19: 0.05 | C19: =((Inputs!$F$16/(1+Inputs!$F$15)*(1-Inputs!$F$17)*(1-Inputs!$F$18))*(1-Inputs!$F$12-0.05)*Inputs!$F$14-Scenarios!G7-Scenarios!G8/5000) | D19: =(((Inputs!$F$16/(1+Inputs!$F$15)*(1-Inputs!$F$17)*(1-Inputs!$F$18))*(1-Inputs!$F$12-0.05)*Inputs!$F$14-Scenarios!G7-Scenarios!G8/5000)*5000-Scenarios!G12-Inputs!$F$19)
A20: Sampling % | B20: 0.1 | C20: =((Inputs!$F$16/(1+Inputs!$F$15)*(1-Inputs!$F$17)*(1-Inputs!$F$18))*(1-Inputs!$F$12-0.1)*Inputs!$F$14-Scenarios!G7-Scenarios!G8/5000) | D20: =(((Inputs!$F$16/(1+Inputs!$F$15)*(1-Inputs!$F$17)*(1-Inputs!$F$18))*(1-Inputs!$F$12-0.1)*Inputs!$F$14-Scenarios!G7-Scenarios!G8/5000)*5000-Scenarios!G12-Inputs!$F$19)
A21: Sampling % | B21: 0.2 | C21: =((Inputs!$F$16/(1+Inputs!$F$15)*(1-Inputs!$F$17)*(1-Inputs!$F$18))*(1-Inputs!$F$12-0.2)*Inputs!$F$14-Scenarios!G7-Scenarios!G8/5000) | D21: =(((Inputs!$F$16/(1+Inputs!$F$15)*(1-Inputs!$F$17)*(1-Inputs!$F$18))*(1-Inputs!$F$12-0.2)*Inputs!$F$14-Scenarios!G7-Scenarios!G8/5000)*5000-Scenarios!G12-Inputs!$F$19)
A22: Fruit adder Rs/can (HYPOTHETICAL) | B22: 5 | C22: =((Inputs!$F$16/(1+Inputs!$F$15)*(1-Inputs!$F$17)*(1-Inputs!$F$18))*(1-Inputs!$F$12-Inputs!$F$13)*Inputs!$F$14-(Scenarios!G7-Formulation_Inputs!$E$5+5)-Scenarios!G8/5000) | D22: =(((Inputs!$F$16/(1+Inputs!$F$15)*(1-Inputs!$F$17)*(1-Inputs!$F$18))*(1-Inputs!$F$12-Inputs!$F$13)*Inputs!$F$14-(Scenarios!G7-Formulation_Inputs!$E$5+5)-Scenarios!G8/5000)*5000-Scenarios!G12-Inputs!$F$19)
A23: Fruit adder Rs/can (HYPOTHETICAL) | B23: 12 | C23: =((Inputs!$F$16/(1+Inputs!$F$15)*(1-Inputs!$F$17)*(1-Inputs!$F$18))*(1-Inputs!$F$12-Inputs!$F$13)*Inputs!$F$14-(Scenarios!G7-Formulation_Inputs!$E$5+12)-Scenarios!G8/5000) | D23: =(((Inputs!$F$16/(1+Inputs!$F$15)*(1-Inputs!$F$17)*(1-Inputs!$F$18))*(1-Inputs!$F$12-Inputs!$F$13)*Inputs!$F$14-(Scenarios!G7-Formulation_Inputs!$E$5+12)-Scenarios!G8/5000)*5000-Scenarios!G12-Inputs!$F$19)
A24: Fruit adder Rs/can (HYPOTHETICAL) | B24: 25 | C24: =((Inputs!$F$16/(1+Inputs!$F$15)*(1-Inputs!$F$17)*(1-Inputs!$F$18))*(1-Inputs!$F$12-Inputs!$F$13)*Inputs!$F$14-(Scenarios!G7-Formulation_Inputs!$E$5+25)-Scenarios!G8/5000) | D24: =(((Inputs!$F$16/(1+Inputs!$F$15)*(1-Inputs!$F$17)*(1-Inputs!$F$18))*(1-Inputs!$F$12-Inputs!$F$13)*Inputs!$F$14-(Scenarios!G7-Formulation_Inputs!$E$5+25)-Scenarios!G8/5000)*5000-Scenarios!G12-Inputs!$F$19)
A26: Lemon (juice/natural flavour) - 5,000 units
A27: Parameter varied | B27: Value | C27: Contribution per can produced (Rs) | D27: Batch result after one-time + launch (Rs)
A28: MRP Rs | B28: 60 | C28: =((60/(1+Inputs!$F$15)*(1-Inputs!$F$17)*(1-Inputs!$F$18))*(1-Inputs!$F$12-Inputs!$F$13)*Inputs!$F$14-Scenarios!J7-Scenarios!J8/5000) | D28: =(((60/(1+Inputs!$F$15)*(1-Inputs!$F$17)*(1-Inputs!$F$18))*(1-Inputs!$F$12-Inputs!$F$13)*Inputs!$F$14-Scenarios!J7-Scenarios!J8/5000)*5000-Scenarios!J12-Inputs!$F$19)
A29: MRP Rs | B29: 70 | C29: =((70/(1+Inputs!$F$15)*(1-Inputs!$F$17)*(1-Inputs!$F$18))*(1-Inputs!$F$12-Inputs!$F$13)*Inputs!$F$14-Scenarios!J7-Scenarios!J8/5000) | D29: =(((70/(1+Inputs!$F$15)*(1-Inputs!$F$17)*(1-Inputs!$F$18))*(1-Inputs!$F$12-Inputs!$F$13)*Inputs!$F$14-Scenarios!J7-Scenarios!J8/5000)*5000-Scenarios!J12-Inputs!$F$19)
A30: MRP Rs | B30: 80 | C30: =((80/(1+Inputs!$F$15)*(1-Inputs!$F$17)*(1-Inputs!$F$18))*(1-Inputs!$F$12-Inputs!$F$13)*Inputs!$F$14-Scenarios!J7-Scenarios!J8/5000) | D30: =(((80/(1+Inputs!$F$15)*(1-Inputs!$F$17)*(1-Inputs!$F$18))*(1-Inputs!$F$12-Inputs!$F$13)*Inputs!$F$14-Scenarios!J7-Scenarios!J8/5000)*5000-Scenarios!J12-Inputs!$F$19)
A31: MRP Rs | B31: 99 | C31: =((99/(1+Inputs!$F$15)*(1-Inputs!$F$17)*(1-Inputs!$F$18))*(1-Inputs!$F$12-Inputs!$F$13)*Inputs!$F$14-Scenarios!J7-Scenarios!J8/5000) | D31: =(((99/(1+Inputs!$F$15)*(1-Inputs!$F$17)*(1-Inputs!$F$18))*(1-Inputs!$F$12-Inputs!$F$13)*Inputs!$F$14-Scenarios!J7-Scenarios!J8/5000)*5000-Scenarios!J12-Inputs!$F$19)
A32: MRP Rs | B32: 125 | C32: =((125/(1+Inputs!$F$15)*(1-Inputs!$F$17)*(1-Inputs!$F$18))*(1-Inputs!$F$12-Inputs!$F$13)*Inputs!$F$14-Scenarios!J7-Scenarios!J8/5000) | D32: =(((125/(1+Inputs!$F$15)*(1-Inputs!$F$17)*(1-Inputs!$F$18))*(1-Inputs!$F$12-Inputs!$F$13)*Inputs!$F$14-Scenarios!J7-Scenarios!J8/5000)*5000-Scenarios!J12-Inputs!$F$19)
A33: Retailer margin | B33: 0.1 | C33: =((Inputs!$F$16/(1+Inputs!$F$15)*(1-0.1)*(1-Inputs!$F$18))*(1-Inputs!$F$12-Inputs!$F$13)*Inputs!$F$14-Scenarios!J7-Scenarios!J8/5000) | D33: =(((Inputs!$F$16/(1+Inputs!$F$15)*(1-0.1)*(1-Inputs!$F$18))*(1-Inputs!$F$12-Inputs!$F$13)*Inputs!$F$14-Scenarios!J7-Scenarios!J8/5000)*5000-Scenarios!J12-Inputs!$F$19)
A34: Retailer margin | B34: 0.2 | C34: =((Inputs!$F$16/(1+Inputs!$F$15)*(1-0.2)*(1-Inputs!$F$18))*(1-Inputs!$F$12-Inputs!$F$13)*Inputs!$F$14-Scenarios!J7-Scenarios!J8/5000) | D34: =(((Inputs!$F$16/(1+Inputs!$F$15)*(1-0.2)*(1-Inputs!$F$18))*(1-Inputs!$F$12-Inputs!$F$13)*Inputs!$F$14-Scenarios!J7-Scenarios!J8/5000)*5000-Scenarios!J12-Inputs!$F$19)
A35: Retailer margin | B35: 0.3 | C35: =((Inputs!$F$16/(1+Inputs!$F$15)*(1-0.3)*(1-Inputs!$F$18))*(1-Inputs!$F$12-Inputs!$F$13)*Inputs!$F$14-Scenarios!J7-Scenarios!J8/5000) | D35: =(((Inputs!$F$16/(1+Inputs!$F$15)*(1-0.3)*(1-Inputs!$F$18))*(1-Inputs!$F$12-Inputs!$F$13)*Inputs!$F$14-Scenarios!J7-Scenarios!J8/5000)*5000-Scenarios!J12-Inputs!$F$19)
A36: Retailer margin | B36: 0.35 | C36: =((Inputs!$F$16/(1+Inputs!$F$15)*(1-0.35)*(1-Inputs!$F$18))*(1-Inputs!$F$12-Inputs!$F$13)*Inputs!$F$14-Scenarios!J7-Scenarios!J8/5000) | D36: =(((Inputs!$F$16/(1+Inputs!$F$15)*(1-0.35)*(1-Inputs!$F$18))*(1-Inputs!$F$12-Inputs!$F$13)*Inputs!$F$14-Scenarios!J7-Scenarios!J8/5000)*5000-Scenarios!J12-Inputs!$F$19)
A37: Sell-through | B37: 0.4 | C37: =((Inputs!$F$16/(1+Inputs!$F$15)*(1-Inputs!$F$17)*(1-Inputs!$F$18))*(1-Inputs!$F$12-Inputs!$F$13)*0.4-Scenarios!J7-Scenarios!J8/5000) | D37: =(((Inputs!$F$16/(1+Inputs!$F$15)*(1-Inputs!$F$17)*(1-Inputs!$F$18))*(1-Inputs!$F$12-Inputs!$F$13)*0.4-Scenarios!J7-Scenarios!J8/5000)*5000-Scenarios!J12-Inputs!$F$19)
A38: Sell-through | B38: 0.6 | C38: =((Inputs!$F$16/(1+Inputs!$F$15)*(1-Inputs!$F$17)*(1-Inputs!$F$18))*(1-Inputs!$F$12-Inputs!$F$13)*0.6-Scenarios!J7-Scenarios!J8/5000) | D38: =(((Inputs!$F$16/(1+Inputs!$F$15)*(1-Inputs!$F$17)*(1-Inputs!$F$18))*(1-Inputs!$F$12-Inputs!$F$13)*0.6-Scenarios!J7-Scenarios!J8/5000)*5000-Scenarios!J12-Inputs!$F$19)
A39: Sell-through | B39: 0.75 | C39: =((Inputs!$F$16/(1+Inputs!$F$15)*(1-Inputs!$F$17)*(1-Inputs!$F$18))*(1-Inputs!$F$12-Inputs!$F$13)*0.75-Scenarios!J7-Scenarios!J8/5000) | D39: =(((Inputs!$F$16/(1+Inputs!$F$15)*(1-Inputs!$F$17)*(1-Inputs!$F$18))*(1-Inputs!$F$12-Inputs!$F$13)*0.75-Scenarios!J7-Scenarios!J8/5000)*5000-Scenarios!J12-Inputs!$F$19)
A40: Sell-through | B40: 0.95 | C40: =((Inputs!$F$16/(1+Inputs!$F$15)*(1-Inputs!$F$17)*(1-Inputs!$F$18))*(1-Inputs!$F$12-Inputs!$F$13)*0.95-Scenarios!J7-Scenarios!J8/5000) | D40: =(((Inputs!$F$16/(1+Inputs!$F$15)*(1-Inputs!$F$17)*(1-Inputs!$F$18))*(1-Inputs!$F$12-Inputs!$F$13)*0.95-Scenarios!J7-Scenarios!J8/5000)*5000-Scenarios!J12-Inputs!$F$19)
A41: Sampling % | B41: 0.05 | C41: =((Inputs!$F$16/(1+Inputs!$F$15)*(1-Inputs!$F$17)*(1-Inputs!$F$18))*(1-Inputs!$F$12-0.05)*Inputs!$F$14-Scenarios!J7-Scenarios!J8/5000) | D41: =(((Inputs!$F$16/(1+Inputs!$F$15)*(1-Inputs!$F$17)*(1-Inputs!$F$18))*(1-Inputs!$F$12-0.05)*Inputs!$F$14-Scenarios!J7-Scenarios!J8/5000)*5000-Scenarios!J12-Inputs!$F$19)
A42: Sampling % | B42: 0.1 | C42: =((Inputs!$F$16/(1+Inputs!$F$15)*(1-Inputs!$F$17)*(1-Inputs!$F$18))*(1-Inputs!$F$12-0.1)*Inputs!$F$14-Scenarios!J7-Scenarios!J8/5000) | D42: =(((Inputs!$F$16/(1+Inputs!$F$15)*(1-Inputs!$F$17)*(1-Inputs!$F$18))*(1-Inputs!$F$12-0.1)*Inputs!$F$14-Scenarios!J7-Scenarios!J8/5000)*5000-Scenarios!J12-Inputs!$F$19)
...

Sheet Breakeven_MRP
A1: WHAT MUST BE TRUE: minimum MRP (incl. GST) for each scenario
A3: Scenario | B3: Cost per can SOLD | C3: MRP to break even on the batch | D3: MRP to also recover one-time + launch from THIS batch | E3: Compare: Sting Rs 20 (250 ml), Red Bull Rs 125 (250 ml)
A4: Powder (artificial flavour) x 2,000 | B4: =Scenarios!C26 | C4: =Scenarios!C26/((1-Inputs!$F$17)*(1-Inputs!$F$18))*(1+Inputs!$F$15) | D4: =(Scenarios!C10+Scenarios!C12+Inputs!$F$19)/Scenarios!C16/((1-Inputs!$F$17)*(1-Inputs!$F$18))*(1+Inputs!$F$15)
A5: Powder (artificial flavour) x 5,000 | B5: =Scenarios!D26 | C5: =Scenarios!D26/((1-Inputs!$F$17)*(1-Inputs!$F$18))*(1+Inputs!$F$15) | D5: =(Scenarios!D10+Scenarios!D12+Inputs!$F$19)/Scenarios!D16/((1-Inputs!$F$17)*(1-Inputs!$F$18))*(1+Inputs!$F$15)
A6: Powder (artificial flavour) x 10,000 | B6: =Scenarios!E26 | C6: =Scenarios!E26/((1-Inputs!$F$17)*(1-Inputs!$F$18))*(1+Inputs!$F$15) | D6: =(Scenarios!E10+Scenarios!E12+Inputs!$F$19)/Scenarios!E16/((1-Inputs!$F$17)*(1-Inputs!$F$18))*(1+Inputs!$F$15)
A7: Blueberry (real fruit/juice) x 2,000 | B7: =Scenarios!F26 | C7: =Scenarios!F26/((1-Inputs!$F$17)*(1-Inputs!$F$18))*(1+Inputs!$F$15) | D7: =(Scenarios!F10+Scenarios!F12+Inputs!$F$19)/Scenarios!F16/((1-Inputs!$F$17)*(1-Inputs!$F$18))*(1+Inputs!$F$15)
A8: Blueberry (real fruit/juice) x 5,000 | B8: =Scenarios!G26 | C8: =Scenarios!G26/((1-Inputs!$F$17)*(1-Inputs!$F$18))*(1+Inputs!$F$15) | D8: =(Scenarios!G10+Scenarios!G12+Inputs!$F$19)/Scenarios!G16/((1-Inputs!$F$17)*(1-Inputs!$F$18))*(1+Inputs!$F$15)
A9: Blueberry (real fruit/juice) x 10,000 | B9: =Scenarios!H26 | C9: =Scenarios!H26/((1-Inputs!$F$17)*(1-Inputs!$F$18))*(1+Inputs!$F$15) | D9: =(Scenarios!H10+Scenarios!H12+Inputs!$F$19)/Scenarios!H16/((1-Inputs!$F$17)*(1-Inputs!$F$18))*(1+Inputs!$F$15)
A10: Lemon (juice/natural flavour) x 2,000 | B10: =Scenarios!I26 | C10: =Scenarios!I26/((1-Inputs!$F$17)*(1-Inputs!$F$18))*(1+Inputs!$F$15) | D10: =(Scenarios!I10+Scenarios!I12+Inputs!$F$19)/Scenarios!I16/((1-Inputs!$F$17)*(1-Inputs!$F$18))*(1+Inputs!$F$15)
A11: Lemon (juice/natural flavour) x 5,000 | B11: =Scenarios!J26 | C11: =Scenarios!J26/((1-Inputs!$F$17)*(1-Inputs!$F$18))*(1+Inputs!$F$15) | D11: =(Scenarios!J10+Scenarios!J12+Inputs!$F$19)/Scenarios!J16/((1-Inputs!$F$17)*(1-Inputs!$F$18))*(1+Inputs!$F$15)
A12: Lemon (juice/natural flavour) x 10,000 | B12: =Scenarios!K26 | C12: =Scenarios!K26/((1-Inputs!$F$17)*(1-Inputs!$F$18))*(1+Inputs!$F$15) | D12: =(Scenarios!K10+Scenarios!K12+Inputs!$F$19)/Scenarios!K16/((1-Inputs!$F$17)*(1-Inputs!$F$18))*(1+Inputs!$F$15)
A13: Coconut (coconut-water base) x 2,000 | B13: =Scenarios!L26 | C13: =Scenarios!L26/((1-Inputs!$F$17)*(1-Inputs!$F$18))*(1+Inputs!$F$15) | D13: =(Scenarios!L10+Scenarios!L12+Inputs!$F$19)/Scenarios!L16/((1-Inputs!$F$17)*(1-Inputs!$F$18))*(1+Inputs!$F$15)
A14: Coconut (coconut-water base) x 5,000 | B14: =Scenarios!M26 | C14: =Scenarios!M26/((1-Inputs!$F$17)*(1-Inputs!$F$18))*(1+Inputs!$F$15) | D14: =(Scenarios!M10+Scenarios!M12+Inputs!$F$19)/Scenarios!M16/((1-Inputs!$F$17)*(1-Inputs!$F$18))*(1+Inputs!$F$15)
A15: Coconut (coconut-water base) x 10,000 | B15: =Scenarios!N26 | C15: =Scenarios!N26/((1-Inputs!$F$17)*(1-Inputs!$F$18))*(1+Inputs!$F$15) | D15: =(Scenarios!N10+Scenarios!N12+Inputs!$F$19)/Scenarios!N16/((1-Inputs!$F$17)*(1-Inputs!$F$18))*(1+Inputs!$F$15)

Sheet QComm_D2C
A1: QUICK COMMERCE / D2C: 6-can pack economics (illustrative; fee levels from low-confidence practitioner sources S39/S40)
A3: Item | B3: Quick commerce (Blinkit-type) | C3: Own D2C website | D3: Type | E3: Note
A4: Cans per order | B4: 6 | C4: 6 | D4: ASSUMED
A5: MRP per can (incl. GST) | B5: =Inputs!$F$16 | C5: =Inputs!$F$16 | D5: ASSUMED | E5: links to Inputs
A6: Order value incl. GST | B6: =B4*B5 | C6: =C4*C5 | D6: CALC
A7: Order value ex-GST | B7: =B6/(1+Inputs!$F$15) | C7: =C6/(1+Inputs!$F$15) | D7: CALC
A8: Platform commission % | B8: 0.18 | C8: 0 | D8: RESEARCHED | E8: S39: 10-22%
A9: Commission Rs | B9: =B7*B8 | C9: =C7*C8 | D9: CALC
A10: Fulfilment / shipping per order | B10: 50 | C10: 120 | D10: RESEARCHED / ASSUMED | E10: QC ~Rs 50 (S39); courier for ~1.6 kg assumed Rs 120
A11: Payment gateway % | B11: 0 | C11: 0.02 | D11: ASSUMED
A12: Ad spend per order (CAC allocation) | B12: 60 | C12: 150 | D12: HYPOTHETICAL | E12: Unknown for this category; test.
A13: Product cost (6 x Lemon 5k production cost per can) | B13: =6*Scenarios!J11 | C13: =6*Scenarios!J11 | D13: CALC | E13: links to Scenarios
A14: Contribution per order | B14: =B7-B9-B10-B7*B11-B12-B13 | C14: =C7-C9-C10-C7*C11-C12-C13 | D14: CALC
A15: Contribution per can | B15: =B14/B4 | C15: =C14/C4 | D15: CALC
A16: Fixed listing fee (Blinkit, per SKU per state; returned as ad credit) | B16: 25000 | C16: 0 | D16: RESEARCHED | E16: S39
A17: Orders needed to recover listing fee | B17: =IF(B14>0,B16/B14,"NOT REACHABLE") | C17: n/a | D17: CALC

Sheet Historical_Reference
A1: HISTORICAL REFERENCE ONLY: founder-reported 2025 figures for an ARTIFICIAL-POWDER formulation. NOT applicable to natural-fruit formulations. NOT a current offer.
A4: Manufacturer | B4: Dark Horse Brands (Mahaveer Group), Bengaluru | C4: HISTORICAL
A5: Formulation | B5: Artificial flavour powders (2025 prototype) | C5: HISTORICAL
A6: Minimum order quantity (MOQ) | B6: 2000 | C6: HISTORICAL
A7: Volume at which the lower unit cost applied | B7: 10000 | C7: HISTORICAL
A8: Lower unit cost (Rs/unit), basis unclear: GST, can, freight inclusion UNKNOWN | B8: 22 | C8: HISTORICAL
A9: Unit cost at 2,000-unit MOQ | B9: UNKNOWN: not recalled/documented | C9: UNKNOWN
A10: Proposed selling price considered (Rs); unclear whether MRP or retailer price | B10: 70 | C10: HISTORICAL
A11: MRP ex-GST at 40% (if Rs 70 is MRP) | B11: =B10/(1+Inputs!$F$15) | C11: CALC
A12: Net realisation after base trade margins | B12: =B11*(1-Inputs!$F$17)*(1-Inputs!$F$18) | C12: CALC
A13: Implied contribution per can before freight, waste, samples, unsold | B13: =B12-B8 | C13: CALC
A14: Implied contribution % of net realisation | B14: =B13/B12 | C14: CALC
A16: Reading: even the historical Rs 22 cost leaves a thin margin at a Rs 70 MRP once 40% GST and trade margins are deducted, before any freight, wastage, sampling or unsold stock.

Sheet Quotes_Required
A1: INPUTS THAT REQUIRE FRESH WRITTEN QUOTATIONS (per flavour, at 2,000 / 5,000 / 10,000 units)
A3: # | B3: Quotation needed | C3: From whom | D3: Why it matters
A4: 1 | B4: NPD/formulation fee and number of iterations included, per flavour | C4: 3 contract manufacturers (incl. DH Brands) | D4: Unknown one-time cost; real-fruit work is new R&D.
A5: 2 | B5: Ex-works price per can at 2k/5k/10k, PER FLAVOUR, with what is included (can, end, decoration, ingredients, filling, pasteurisation, secondary pack, testing) | C5: Same 3 | D5: Core of COGS; confirms whether MOQ/price tiers are per flavour or pooled.
A6: 3 | B6: MOQ per flavour vs per run; changeover/cleaning charges; minimum run length | C6: Same 3 | D6: Determines three-flavour vs staged cash.
A7: 4 | B7: Blueberry: juice, puree or concentrate spec (Brix, % inclusion), price/kg, origin, availability | C7: Fruit ingredient suppliers (2-3) | D7: Largest hypothetical cost.
A8: 5 | B8: Lemon: NFC juice vs concentrate vs natural flavour price per can | C8: Flavour houses / juice processors | D8: Cheaper path to a citrus SKU.
A9: 6 | B9: Coconut water: aseptic/frozen supply price per litre, micro specs, minimum volumes; processing route (retort, tunnel pasteurisation, acidification) | C9: Coconut water processors | D9: Low-acid safety and cost.
A10: 7 | B10: Natural flavour systems (blueberry, lemon, coconut) with regulatory declarations | C10: 2 flavour houses | D10: Lower-cost alternative to real fruit.
A11: 8 | B11: Sweetener system (sucralose, ace-K, steviol glycosides), price/kg and recommended blend | C11: Ingredient distributors | D11: Taste and stability.
A12: 9 | B12: Printed can vs plain can + sleeve: MOQ, price, lead time | C12: Can makers / sleeve converters | D12: Printed cans usually need very large MOQs.
A13: 10 | B13: Shelf-life study (real-time + accelerated), micro challenge, caffeine assay, nutrition panel | C13: 2 NABL-accredited labs | D13: Mandatory evidence before sale.
A14: 11 | B14: Regulatory opinion: product category, ingredient permissions, label, claims, naming after the 2026 "energy drink" order | C14: FSSAI regulatory consultant | D14: Can the product be sold as formulated?
A15: 12 | B15: GST classification of each SKU (esp. coconut) | C15: Chartered accountant | D15: 40% vs 5% changes economics.
... A17: 14 | B17: Quick-commerce rate cards (commission, listing, fulfilment, ad minimums) | C17: Blinkit, Zepto, Instamart | D17: Current fees are from blogs only.
